<?xml version='1.0' encoding='utf-8'?>
<robot name="fp_darc">
    <link name="base_footprint"/>

    <link name="base_link">
        <!-- <inertial>
            <origin xyz="-0.014248278630327356 -3.602068440406656e-16 0.08809110166240897" rpy="0.0 0.0 0.0" />
            <mass value="25.370430669503545" />
            <inertia ixx="0.4370021604565135" iyy="0.6193389146359463" izz="0.7959933109951747" ixy="3.1298141373329533e-16" iyz="2.91602746525418e-16" ixz="0.06472885644129679" />
        </inertial> -->
    
        <visual name="base_link_visual">
            <origin xyz="0.0 0.0 0.0" rpy="0.0 0.0 0.0" />
            <geometry>
                <mesh filename="package://fp_darc/meshes/base_link.stl" scale="0.001 0.001 0.001" />
            </geometry>
        </visual>
        <collision name="base_link_collision">
            <origin xyz="0.0 0.0 0.0" rpy="0.0 0.0 0.0" />
            <geometry>
                <mesh filename="package://fp_darc/meshes/base_link.stl" scale="0.001 0.001 0.001" />
            </geometry>
        </collision>
    </link>

    <link name="left_wheel_link">
        <!-- <inertial>
            <origin xyz="2.486899575160351e-16 2.2204460492503132e-17 -0.0022384734261346397" rpy="0.0 -0.0 0.0" />
            <mass value="0.6632556917446788" />
            <inertia ixx="0.00021132652048094433" iyy="0.00021132652048070494" izz="0.0003508009135193262" ixy="-1.3010426069826053e-18" iyz="8.673617379884035e-19" ixz="-3.469446951953614e-18" />
        </inertial> -->
        <visual name="left_wheel_link_visual">
            <origin xyz="0.1307999903473714 -0.032500020853100324 -0.197" rpy="-1.5707963267948966 -0.0 0.0" />
            <geometry>
                <mesh filename="package://fp_darc/meshes/left_wheel_link.stl" scale="0.001 0.001 0.001" />
            </geometry>
        </visual>
        <collision name="left_wheel_link_collision">
            <origin xyz="0.1307999903473714 -0.032500020853100324 -0.197" rpy="-1.5707963267948966 -0.0 0.0" />
            <geometry>
                <mesh filename="package://fp_darc/meshes/left_wheel_link.stl" scale="0.001 0.001 0.001" />
            </geometry>
        </collision>
    </link>

    <link name="right_wheel_link">
        <!-- <inertial>
            <origin xyz="2.6645352591003756e-16 -2.6645352591003756e-17 -0.0022384734261346397" rpy="0.0 -0.0 0.0" />
            <mass value="0.6632556917446787" />
            <inertia ixx="0.0002113265204809478" iyy="0.000211326520480698" izz="0.0003508009135193193" ixy="2.168404344971009e-18" iyz="-2.6020852139652106e-18" ixz="-1.0408340855860843e-17" />
        </inertial> -->
        <visual name="right_wheel_link_visual">
            <origin xyz="0.1307999903473714 0.032500020853100324 -0.197" rpy="1.5707963267948966 -0.0 0.0" />
            <geometry>
                <mesh filename="package://fp_darc/meshes/right_wheel_link.stl" scale="0.001 0.001 0.001" />
            </geometry>
        </visual>
        <collision name="right_wheel_link_collision">
            <origin xyz="0.1307999903473714 0.032500020853100324 -0.197" rpy="1.5707963267948966 -0.0 0.0" />
            <geometry>
                <mesh filename="package://fp_darc/meshes/right_wheel_link.stl" scale="0.001 0.001 0.001" />
            </geometry>
        </collision>
    </link>

    <link name="lidar_link">
        <!-- <inertial>
            <origin xyz="-3.552713678800501e-17 2.1267820881977596e-17 0.01821115335184331" rpy="0.0 -0.0 0.0" />
            <mass value="0.839241294222995" />
            <inertia ixx="0.000296652468627423" iyy="0.000296652468627423" izz="0.000383081144304815" ixy="1.9276740204077112e-19" iyz="-4.1210898004471776e-19" ixz="0.0" />
        </inertial> -->
        <visual name="lidar_link_visual">
            <origin xyz="0.17920000000000003 0.0 -0.23870000000000002" rpy="0.0 -0.0 0.0" />
            <geometry>
                <mesh filename="package://fp_darc/meshes/lidar_link.stl" scale="0.001 0.001 0.001" />
            </geometry>
        </visual>
        <collision name="lidar_link_collision">
            <origin xyz="0.17920000000000003 0.0 -0.23870000000000002" rpy="0.0 -0.0 0.0" />
            <geometry>
                <mesh filename="package://fp_darc/meshes/lidar_link.stl" scale="0.001 0.001 0.001" />
            </geometry>
        </collision>
    </link>
    
    <joint name="base_footprint_base_link_joint" type="fixed">
        <origin xyz="0.0 0.0 0.0" rpy="0.0 0.0 0.0"/>
        <parent link="base_footprint"/>
        <child link="base_link"/>
    </joint>
    
    <joint name="base_link_right_wheel_joint" type="continuous">
        <origin xyz="-0.1308 0.196 0.0325" rpy="-1.5707963267948966 -0.0 0.0" />
        <parent link="base_link" />
        <child link="right_wheel_link" />
        <axis xyz="0.0 0.0 1.0" />
    </joint>
    <joint name="base_link_left_wheel_joint" type="continuous">
        <origin xyz="-0.1308 -0.196 0.0325" rpy="1.5707963267948966 -0.0 0.0" />
        <parent link="base_link" />
        <child link="left_wheel_link" />
        <axis xyz="0.0 0.0 1.0" />
    </joint>
    <joint name="base_link_lidar_joint" type="fixed">
        <origin xyz="-0.17920000000000003 0.0 0.23870000000000002" rpy="0.0 -0.0 0.0" />
        <parent link="base_link" />
        <child link="lidar_link" />
    </joint>
</robot>