<?xml version='1.0' encoding='utf-8'?>
<robot name="fp_darc">
    <link name="base_footprint"/>

    <link name="base_link">
        <!-- <inertial>
            <origin xyz="0.014248278630327266 -1.1256463876270833e-16 0.08809110166240894" rpy="0.0 0.0 0.0" />
            <mass value="25.370430669503467" />
            <inertia ixx="0.43700216045651286" iyy="0.6193389146359399" izz="0.7959933109951695" ixy="-3.1478153640812046e-15" iyz="-2.5157174533884612e-16" ixz="-0.06472885644129664" />
        </inertial> -->
        <visual name="base_link_visual">
            <origin xyz="0.0 0.0 0.0" rpy="0.0 0.0 0.0" />
            <geometry>
                <mesh filename="package://fp_darc/meshes/base_link.stl" scale="0.001 0.001 0.001" />
            </geometry>
        </visual>
        <collision name="base_link_collision">
            <origin xyz="0.0 0.0 0.0" rpy="0.0 0.0 0.0" />
            <geometry>
                <mesh filename="package://fp_darc/meshes/base_link.stl" scale="0.001 0.001 0.001" />
            </geometry>
        </collision>
    </link>

    <link name="left_wheel_link">
        <!-- <inertial>
            <origin xyz="-2.842170943040401e-16 -4.4408920985006264e-17 -0.0022384734261346397" rpy="0.0 -0.0 0.0" />
            <mass value="0.6632556917446785" />
            <inertia ixx="0.00021132652048095127" iyy="0.00021132652048070494" izz="0.00035080091351932796" ixy="-8.673617379884035e-19" iyz="-1.734723475976807e-18" ixz="3.469446951953614e-18" />
        </inertial> -->
        <visual name="left_wheel_link_visual">
            <origin xyz="-0.1308000096526286 0.032500020853100324 -0.19500000000000003" rpy="1.5707963267948966 -0.0 0.0" />
            <geometry>
                <mesh filename="package://fp_darc/meshes/left_wheel_link.stl" scale="0.001 0.001 0.001" />
            </geometry>
        </visual>
        <collision name="left_wheel_link_collision">
            <origin xyz="-0.1308000096526286 0.032500020853100324 -0.19500000000000003" rpy="1.5707963267948966 -0.0 0.0" />
            <geometry>
                <mesh filename="package://fp_darc/meshes/left_wheel_link.stl" scale="0.001 0.001 0.001" />
            </geometry>
        </collision>
    </link>

    <link name="right_wheel_link">
        <!-- <inertial>
            <origin xyz="-3.375077994860476e-16 2.2204460492503132e-17 -0.0022384734261346397" rpy="0.0 -0.0 0.0" />
            <mass value="0.6632556917446786" />
            <inertia ixx="0.00021132652048094433" iyy="0.00021132652048071882" izz="0.00035080091351933837" ixy="-1.734723475976807e-18" iyz="-8.673617379884035e-19" ixz="-6.938893903907228e-18" />
        </inertial> -->
        <visual name="right_wheel_link_visual">
            <origin xyz="-0.1308000096526286 -0.032500020853100324 -0.19500000000000003" rpy="-1.5707963267948966 -0.0 0.0" />
            <geometry>
                <mesh filename="package://fp_darc/meshes/right_wheel_link.stl" scale="0.001 0.001 0.001" />
            </geometry>
        </visual>
        <collision name="right_wheel_link_collision">
            <origin xyz="-0.1308000096526286 -0.032500020853100324 -0.19500000000000003" rpy="-1.5707963267948966 -0.0 0.0" />
            <geometry>
                <mesh filename="package://fp_darc/meshes/right_wheel_link.stl" scale="0.001 0.001 0.001" />
            </geometry>
        </collision>
    </link>

    <link name="lidar_link">
        <!-- <inertial>
            <origin xyz="0.0 -5.316955220494399e-18 0.01821115335184331" rpy="0.0 -0.0 0.0" />
            <mass value="0.839241294222995" />
            <inertia ixx="0.00029665246862740913" iyy="0.00029665246862740913" izz="0.00038308114430482196" ixy="-8.888719094102273e-19" iyz="1.9227141262264804e-19" ixz="0.0" />
        </inertial> -->
        <visual name="lidar_link_visual">
            <origin xyz="-0.17920000000000003 0.0 -0.23870000000000002" rpy="0.0 -0.0 0.0" />
            <geometry>
                <mesh filename="package://fp_darc/meshes/lidar_link.stl" scale="0.001 0.001 0.001" />
            </geometry>
        </visual>
        <collision name="lidar_link_collision">
            <origin xyz="-0.17920000000000003 0.0 -0.23870000000000002" rpy="0.0 -0.0 0.0" />
            <geometry>
                <mesh filename="package://fp_darc/meshes/lidar_link.stl" scale="0.001 0.001 0.001" />
            </geometry>
        </collision>
    </link>

    <joint name="base_footprint_base_link_joint" type="fixed">
        <origin xyz="0.0 0.0 0.0" rpy="0.0 0.0 0.0"/>
        <parent link="base_footprint"/>
        <child link="base_link"/>
    </joint>

    <joint name="base_link_right_wheel_joint" type="continuous">
        <origin xyz="0.1308 -0.196 0.0325" rpy="1.5707963267948966 -0.0 0.0" />
        <parent link="base_link" />
        <child link="right_wheel_link" />
        <axis xyz="0.0 0.0 1.0" />
    </joint>
    
    <joint name="base_link_left_wheel_joint" type="continuous">
        <origin xyz="0.1308 0.196 0.0325" rpy="-1.5707963267948966 -0.0 0.0" />
        <parent link="base_link" />
        <child link="left_wheel_link" />
        <axis xyz="0.0 0.0 1.0" />
    </joint>
    <joint name="base_link_lidar_joint" type="fixed">
        <origin xyz="0.17920000000000003 0.0 0.23870000000000002" rpy="0.0 -0.0 0.0" />
        <parent link="base_link" />
        <child link="lidar_link" />
    </joint>
</robot>