<?xml version="1.0"?>
<robot xmlns:xacro="http://www.ros.org/wiki/xacro" name="sweebo">

<xacro:include filename="$(find fp_darc)/urdf/materials.xacro" />


<link name="base_footprint"/>

<link name="base_link">
    <!-- <inertial>
        <origin xyz="0.0 0.0 0.0" rpy="0.0 0.0 0.0"/>
        <mass value="0.0"/>
        <inertia ixx="0.0" ixy="0.0" ixz="0.0" iyy="0.0" iyz="0.0" izz="0.0"/>
    </inertial> -->
    <visual>
        <origin xyz="0.0 0.0 0.0" rpy="0.0 0.0 0.0"/>
        <geometry>
            <mesh filename="package://fp_darc/meshes/base_link.stl" scale="0.001 0.001 0.001" />
        </geometry>
        <material name="silver"/>
    </visual>
    <collision>
        <origin xyz="0.0 0.0 0.0" rpy="0.0 0.0 0.0"/>
        <geometry>
            <mesh filename="package://fp_darc/meshes/base_link.stl" scale="0.001 0.001 0.001" />
        </geometry>
    </collision>
</link>

<link name="right_wheel_link">
    <!-- <inertial>
        <origin xyz="0.0 0.0 0.0" rpy="0.0 0.0 0.0"/>
        <mass value="0.0"/>
        <inertia ixx="0.0" ixy="0.0" ixz="0.0" iyy="0.0" iyz="0.0" izz="0.0"/>
    </inertial> -->
    <visual>
        <origin xyz="-0.13080 0.190 -0.0325" rpy="0.0 0.0 0.0"/>
        <geometry>
            <mesh filename="package://fp_darc/meshes/right_wheel_link.stl" scale="0.001 0.001 0.001" />
        </geometry>
        <material name="black"/>
    </visual>
    <collision>
        <origin xyz="-0.13080 0.190 -0.0325" rpy="0.0 0.0 0.0"/>
        <geometry>
            <mesh filename="package://fp_darc/meshes/right_wheel_link.stl" scale="0.001 0.001 0.001" />
        </geometry>
    </collision>
</link>

<link name="left_wheel_link">
    <!-- <inertial>
        <origin xyz="0.0 0.0 0.0" rpy="0.0 0.0 0.0"/>
        <mass value="0.0"/>
        <inertia ixx="0.0" ixy="0.0" ixz="0.0" iyy="0.0" iyz="0.0" izz="0.0"/>
    </inertial> -->
    <visual>
        <origin xyz="-0.13080 -0.190 -0.0325" rpy="0.0 0.0 0.0"/>
        <geometry>
            <mesh filename="package://fp_darc/meshes/left_wheel_link.stl" scale="0.001 0.001 0.001" />
        </geometry>
        <material name="black"/>
    </visual>
    <collision>
        <origin xyz="-0.13080 -0.190 -0.0325" rpy="0.0 0.0 0.0"/>
        <geometry>
            <mesh filename="package://fp_darc/meshes/left_wheel_link.stl" scale="0.001 0.001 0.001" />
        </geometry>
    </collision>
</link>

<link name="lidar_link">
    <!-- <inertial>
        <origin xyz="0.0 0.0 0.0" rpy="0.0 0.0 0.0"/>
        <mass value="0.0"/>
        <inertia ixx="0.0" ixy="0.0" ixz="0.0" iyy="0.0" iyz="0.0" izz="0.0"/>
    </inertial> -->
    <visual>
        <origin xyz="-0.1792 -0.0 -0.2689" rpy="0.0 0.0 0.0"/>
        <geometry>
            <mesh filename="package://fp_darc/meshes/lidar_link.stl" scale="0.001 0.001 0.001" />
        </geometry>
        <material name="black"/>
    </visual>
    <collision>
        <origin xyz="-0.1792 -0.0 -0.2689" rpy="0.0 0.0 0.0"/>
        <geometry>
            <mesh filename="package://fp_darc/meshes/lidar_link.stl" scale="0.001 0.001 0.001" />
        </geometry>
    </collision>
</link>

<joint name="base_joint" type="fixed">
    <origin xyz="0.0 0.0 0.0" rpy="0.0 0.0 0.0"/>
    <parent link="base_footprint"/>
    <child link="base_link"/>
</joint>

<joint name="right_wheel_joint" type="continuous">
    <origin xyz="0.13080 -0.190 0.0325" rpy="0.0 0.0 0.0"/>
    <parent link="base_link"/>
    <child link="right_wheel_link"/>
    <axis xyz="0.0 1.0 0.0"/>
</joint>

<joint name="left_wheel_joint" type="continuous">
    <origin xyz="0.13080 0.190 0.0325" rpy="0.0 0.0 0.0"/>
    <parent link="base_link"/>
    <child link="left_wheel_link"/>
    <axis xyz="0.0 1.0 0.0"/>
</joint>

<joint name="lidar_joint" type="fixed">
    <origin xyz="0.1792 0.0 0.2689" rpy="0.0 0.0 0.0"/>
    <parent link="base_link"/>
    <child link="lidar_link"/>
</joint>

</robot>